Workbook

Sheet ARV_Clean_Data
B2: ID | C2: PO / SO # | D2: ASN/DN # | E2: Country | F2: Product Group | G2: Sub Classification | H2: Vendor | I2: Fulfill Via | J2: Vendor INCO Term | K2: Shipment Mode | L2: PO Sent to Vendor Date | M2: Scheduled Delivery Date | N2: Delivered to Client Date | O2: Delivery Recorded Date | P2: Item Description | Q2: Molecule/Test Type | R2: Brand | S2: Dosage | T2: Dosage Form | U2: Unit of Measure (Per Pack) | V2: Line Item Quantity | W2: Line Item Value | X2: Pack Price | Y2: Unit Price | Z2: Weight (Kilograms) | AA2: Freight Cost (USD) | AB2: On_time_flag | AC2: Delivery Recorded Date - Copy
B3: 45 | C3: SCMS-140 | D3: ASN-94 | E3: Tanzania | F3: ARV | G3: Adult | H3: Aurobindo Pharma Limited | I3: Direct Drop | J3: EXW | K3: Air | M3: 39045 | N3: 39045 | O3: 39045 | P3: Nevirapine 200mg, tablets, 60 Tabs | Q3: Nevirapine | R3: Generic | S3: 200mg | T3: Tablet | U3: 60 | V3: 16667 | W3: 60834.55 | X3: 3.65 | Y3: 0.06 | Z3: 1478 | AA3: 6212.41 | AB3: 1 | AC3: 2006 | AE3: {=+(tblARV[Line Item Quantity]*tblARV[Unit Price])} -> 1000.02
B4: 64 | C4: SCMS-268 | D4: ASN-242 | E4: Rwanda | F4: ARV | G4: Adult | H4: CIPLA LIMITED | I4: Direct Drop | J4: EXW | K4: Air | L4: 39073 | M4: 39140 | N4: 39140 | O4: 39140 | P4: Lamivudine/Zidovudine 150/300mg, tablets, 60 Tabs | Q4: Lamivudine/Zidovudine | R4: Generic | S4: 150/300mg | T4: Tablet - FDC | U4: 60 | V4: 10000 | W4: 99800 | X4: 9.98 | Y4: 0.17 | Z4: 7416 | AA4: 64179.42 | AB4: 1 | AC4: 2007 | AE4: 1700
B5: 87 | C5: SCMS-555 | D5: ASN-409 | E5: Tanzania | F5: ARV | G5: Pediatric | H5: BRISTOL-MYERS SQUIBB | I5: Direct Drop | J5: CIP | K5: Air | L5: 39184 | M5: 39239 | N5: 39239 | O5: 39239 | P5: Didanosine 2g [Videx], powder for oral solution 10mg/ml, reconstitute to 200 ml | Q5: Didanosine | R5: Videx | S5: 2g | T5: Powder for oral solution | U5: 200 | V5: 712 | W5: 8964.08 | X5: 12.59 | Y5: 0.06 | Z5: 162 | AA5: 912.96 | AB5: 1 | AC5: 2007 | AE5: 42.72
B6: 161 | C6: SCMS-11070 | D6: ASN-916 | E6: Ethiopia | F6: ARV | G6: Adult | H6: Aurobindo Pharma Limited | I6: Direct Drop | J6: EXW | K6: Air | L6: 39358 | M6: 39406 | N6: 39406 | O6: 39406 | P6: Stavudine 30mg, capsules, 60 Caps | Q6: Stavudine | R6: Generic | S6: 30mg | T6: Capsule | U6: 60 | V6: 64000 | W6: 99200 | X6: 1.55 | Y6: 0.03 | Z6: 4228 | AA6: 12237.61 | AB6: 1 | AC6: 2007 | AE6: 1920
B7: 535 | C7: SCMS-23610 | D7: ASN-2167 | E7: Tanzania | F7: ARV | G7: Adult | H7: BRISTOL-MYERS SQUIBB | I7: Direct Drop | J7: CIP | K7: Air | L7: 39583 | M7: 39693 | N7: 39693 | O7: 39693 | P7: Didanosine EC 400mg [Videx EC], delayed-release capsules, Blister 3 x 10 Caps | Q7: Didanosine EC | R7: Videx EC | S7: 400mg | T7: Delayed-release capsules - blister | U7: 30 | V7: 2597 | W7: 61470.99 | X7: 23.67 | Y7: 0.79 | Z7: 117 | AA7: 645.1 | AB7: 1 | AC7: 2008 | AE7: 2051.63
B8: 858 | C8: SCMS-34680 | D8: ASN-3332 | E8: Tanzania | F8: ARV | G8: Adult | H8: MERCK SHARP & DOHME IDEA GMBH (FORMALLY MERCK SHARP & DOHME B.V.) | I8: Direct Drop | J8: CIP | K8: Air | L8: 39801 | M8: 39924 | N8: 39924 | O8: 39924 | P8: Efavirenz/Emtricitabine/Tenofovir Disoproxil Fumarate 600/200/300mg [Atripla], tablets, 30 Tabs | Q8: Efavirenz/Emtricitabine/Tenofovir Disoproxil Fumarate | R8: Atripla | S8: 600/200/300mg | T8: Tablet - FDC | U8: 30 | V8: 50000 | W8: 2520000 | X8: 50.4 | Y8: 1.68 | Z8: 4093 | AA8: 9339 | AB8: 1 | AC8: 2009 | AE8: 84000
B9: 985 | C9: SCMS-38370 | D9: ASN-3751 | E9: Tanzania | F9: ARV | G9: Pediatric | H9: ABBVIE LOGISTICS (FORMERLY ABBOTT LOGISTICS BV) | I9: Direct Drop | J9: FCA | K9: Air | L9: 39849 | M9: 39961 | N9: 39961 | O9: 39961 | P9: Lopinavir/Ritonavir 80/20mg/ml [Kaletra], oral solution, cool, Bottle 5 x 60 ml | Q9: Lopinavir/Ritonavir | R9: Kaletra | S9: 80/20mg/ml | T9: Oral solution | U9: 300 | V9: 524 | W9: 21536.4 | X9: 41.1 | Y9: 0.14 | Z9: 644 | AA9: 6668.61 | AB9: 1 | AC9: 2009 | AE9: 73.36
B10: 986 | C10: SCMS-38380 | D10: ASN-3627 | E10: Tanzania | F10: ARV | G10: Pediatric | H10: ABBVIE LOGISTICS (FORMERLY ABBOTT LOGISTICS BV) | I10: Direct Drop | J10: FCA | K10: Air | L10: 39849 | M10: 39937 | N10: 39937 | O10: 39937 | P10: Lopinavir/Ritonavir 100/25mg [Aluvia], tablets, 60 Tabs | Q10: Lopinavir/Ritonavir | R10: Generic | S10: 100/25mg | T10: Tablet | U10: 60 | V10: 2094 | W10: 21526.32 | X10: 10.28 | Y10: 0.17 | Z10: 237 | AB10: 1 | AC10: 2009 | AE10: 355.98
B11: 1156 | C11: SCMS-43890 | D11: ASN-4503 | E11: Rwanda | F11: ARV | G11: Adult | H11: HETERO LABS LIMITED | I11: Direct Drop | J11: CIP | K11: Air | L11: 39918 | M11: 40019 | N11: 40019 | O11: 40019 | P11: Efavirenz 600mg, tablets, 30 Tabs | Q11: Efavirenz | R11: Generic | S11: 600mg | T11: Tablet | U11: 30 | V11: 55356 | W11: 386384.88 | X11: 6.98 | Y11: 0.23 | Z11: 4482 | AA11: 37404.74 | AB11: 1 | AC11: 2009 | AE11: 12731.88
B12: 1299 | C12: SCMS-268 | D12: ASN-242 | E12: Rwanda | F12: ARV | G12: Adult | H12: CIPLA LIMITED | I12: Direct Drop | J12: EXW | K12: Air | L12: 39073 | M12: 39140 | N12: 39140 | O12: 39140 | P12: Efavirenz 600mg, tablets, 30 Tabs | Q12: Efavirenz | R12: Generic | S12: 600mg | T12: Tablet | U12: 30 | V12: 71577 | W12: 1087970.4 | X12: 15.2 | Y12: 0.51 | AB12: 1 | AC12: 2007 | AE12: 36504.27
B13: 1300 | C13: SCMS-268 | D13: ASN-242 | E13: Rwanda | F13: ARV | G13: Adult | H13: CIPLA LIMITED | I13: Direct Drop | J13: EXW | K13: Air | L13: 39073 | M13: 39140 | N13: 39140 | O13: 39140 | P13: Abacavir 300mg, tablets, 60 Tabs | Q13: Abacavir | R13: Generic | S13: 300mg | T13: Tablet | U13: 60 | V13: 5605 | W13: 202340.5 | X13: 36.1 | Y13: 0.6 | AB13: 1 | AC13: 2007 | AE13: 3363
B14: 1502 | C14: SCMS-13900 | D14: ASN-990 | E14: Rwanda | F14: ARV | G14: Adult | H14: ASPEN PHARMACARE | I14: Direct Drop | J14: EXW | K14: Air | L14: 39398 | M14: 39475 | N14: 39475 | O14: 39475 | P14: Tenofovir Disoproxil Fumarate 300mg [Viread], tablets, 30 Tabs | Q14: Tenofovir Disoproxil Fumarate | R14: Viread | S14: 300mg | T14: Tablet | U14: 30 | V14: 1609 | W14: 27353 | X14: 17 | Y14: 0.57 | Z14: 157 | AA14: 7922.24 | AB14: 1 | AC14: 2008 | AE14: 917.13
B15: 1529 | C15: SCMS-14750 | D15: ASN-1194 | E15: Rwanda | F15: ARV | G15: Adult | H15: MYLAN LABORATORIES LTD (FORMERLY MATRIX LABORATORIES) | I15: Direct Drop | J15: CIP | K15: Air | L15: 39419 | M15: 39475 | N15: 39475 | O15: 39475 | P15: Abacavir 300mg, tablets, 60 Tabs | Q15: Abacavir | R15: Generic | S15: 300mg | T15: Tablet | U15: 60 | V15: 1099 | W15: 30222.5 | X15: 27.5 | Y15: 0.46 | Z15: 113 | AA15: 1511.25 | AB15: 1 | AC15: 2008 | AE15: 505.54
B16: 1888 | C16: SCMS-25520 | D16: ASN-2079 | E16: Rwanda | F16: ARV | G16: Adult | H16: Aurobindo Pharma Limited | I16: Direct Drop | J16: CIP | K16: Air | L16: 39612 | M16: 39652 | N16: 39651 | O16: 39651 | P16: Lamivudine/Nevirapine/Zidovudine 150/200/300mg, tablets, 60 Tabs | Q16: Lamivudine/Nevirapine/Zidovudine | R16: Generic | S16: 150/300/200mg | T16: Tablet - FDC | U16: 60 | V16: 47879 | W16: 569281.31 | X16: 11.89 | Y16: 0.2 | Z16: 5311 | AA16: 30408.04 | AB16: 1 | AC16: 2008 | AE16: 9575.8
B17: 1889 | C17: SCMS-25520 | D17: ASN-2080 | E17: Rwanda | F17: ARV | G17: Adult | H17: Aurobindo Pharma Limited | I17: Direct Drop | J17: CIP | K17: Air | L17: 39612 | M17: 39652 | N17: 39652 | O17: 39652 | P17: Lamivudine/Nevirapine/Zidovudine 150/200/300mg, tablets, 60 Tabs | Q17: Lamivudine/Nevirapine/Zidovudine | R17: Generic | S17: 150/300/200mg | T17: Tablet - FDC | U17: 60 | V17: 61021 | W17: 725539.69 | X17: 11.89 | Y17: 0.2 | Z17: 6768 | AA17: 38120.96 | AB17: 1 | AC17: 2008 | AE17: 12204.2
B18: 2441 | C18: SCMS-41240 | D18: ASN-3904 | E18: Uganda | F18: ARV | G18: Adult | H18: BRISTOL-MYERS SQUIBB | I18: Direct Drop | J18: CIP | K18: Air | L18: 39891 | M18: 39937 | N18: 39937 | O18: 39937 | P18: Didanosine EC 250mg [Videx EC], delayed-release capsules, Blister 3 x 10 Caps | Q18: Didanosine EC | R18: Videx EC | S18: 250mg | T18: Delayed-release capsules - blister | U18: 30 | V18: 60 | W18: 1100.4 | X18: 18.34 | Y18: 0.61 | Z18: 3000 | AA18: 428.91 | AB18: 1 | AC18: 2009 | AE18: 36.6
B19: 2463 | C19: SCMS-30312 | D19: ASN-3851 | E19: Rwanda | F19: ARV | G19: Adult | H19: CIPLA LIMITED | I19: Direct Drop | J19: CIP | K19: Air | L19: 39742 | M19: 39923 | N19: 39923 | O19: 39923 | P19: Lamivudine/Zidovudine 150/300mg, tablets, 60 Tabs | Q19: Lamivudine/Zidovudine | R19: Generic | S19: 150/300mg | T19: Tablet - FDC | U19: 60 | V19: 7840 | W19: 71344 | X19: 9.1 | Y19: 0.15 | Z19: 719 | AA19: 853.88 | AB19: 1 | AC19: 2009 | AE19: 1176
B20: 2536 | C20: SCMS-43880 | D20: ASN-4462 | E20: Rwanda | F20: ARV | G20: Adult | H20: MYLAN LABORATORIES LTD (FORMERLY MATRIX LABORATORIES) | I20: Direct Drop | J20: CIP | K20: Air | L20: 39918 | M20: 40014 | N20: 40014 | O20: 40014 | P20: Lamivudine/Nevirapine/Zidovudine 150/200/300mg, tablets, 60 Tabs | Q20: Lamivudine/Nevirapine/Zidovudine | R20: Generic | S20: 150/300/200mg | T20: Tablet - FDC | U20: 60 | V20: 26932 | W20: 317528.28 | X20: 11.79 | Y20: 0.2 | Z20: 3393 | AA20: 30661.5 | AB20: 1 | AC20: 2009 | AE20: 5386.4
B21: 2808 | C21: SCMS-11071 | D21: ASN-1039 | E21: Ethiopia | F21: ARV | G21: Adult | H21: Aurobindo Pharma Limited | I21: Direct Drop | J21: EXW | K21: Air | L21: 39358 | M21: 39406 | N21: 39440 | O21: 39440 | P21: Stavudine 30mg, capsules, 60 Caps | Q21: Stavudine | R21: Generic | S21: 30mg | T21: Capsule | U21: 60 | V21: 35065 | W21: 54350.75 | X21: 1.55 | Y21: 0.03 | Z21: 2318 | AA21: 6755.81 | AB21: 0 | AC21: 2007 | AE21: 1051.95
B22: 2892 | C22: SCMS-13510 | D22: ASN-1483 | E22: Uganda | F22: ARV | G22: Adult | H22: BRISTOL-MYERS SQUIBB | I22: Direct Drop | J22: CIP | K22: Air | L22: 39358 | M22: 39538 | N22: 39538 | O22: 39538 | P22: Didanosine EC 400mg [Videx EC], delayed-release capsules, Blister 3 x 10 Caps | Q22: Didanosine EC | R22: Videx EC | S22: 400mg | T22: Delayed-release capsules - blister | U22: 30 | V22: 140 | W22: 3313.8 | X22: 23.67 | Y22: 0.79 | Z22: 6 | AB22: 1 | AC22: 2008 | AE22: 110.6
B23: 3294 | C23: SCMS-27190 | D23: ASN-2391 | E23: Uganda | F23: ARV | G23: Adult | H23: BRISTOL-MYERS SQUIBB | I23: Direct Drop | J23: CIP | K23: Air | L23: 39647 | M23: 39700 | N23: 39700 | O23: 39700 | P23: Didanosine EC 400mg [Videx EC], delayed-release capsules, Blister 3 x 10 Caps | Q23: Didanosine EC | R23: Videx EC | S23: 400mg | T23: Delayed-release capsules - blister | U23: 30 | V23: 50 | W23: 1183.5 | X23: 23.67 | Y23: 0.79 | Z23: 2 | AA23: 330 | AB23: 1 | AC23: 2008 | AE23: 39.5
B24: 3470 | C24: SCMS-32250 | D24: ASN-3001 | E24: Uganda | F24: ARV | G24: Adult | H24: BRISTOL-MYERS SQUIBB | I24: Direct Drop | J24: CIP | K24: Air | L24: 39738 | M24: 39791 | N24: 39791 | O24: 39791 | P24: Didanosine EC 250mg [Videx EC], delayed-release capsules, Blister 3 x 10 Caps | Q24: Didanosine EC | R24: Videx EC | S24: 250mg | T24: Delayed-release capsules - blister | U24: 30 | V24: 50 | W24: 917 | X24: 18.34 | Y24: 0.61 | Z24: 2 | AA24: 378 | AB24: 1 | AC24: 2008 | AE24: 30.5
B25: 3828 | C25: SCMS-43870 | D25: ASN-4687 | E25: Rwanda | F25: ARV | G25: Adult | H25: MYLAN LABORATORIES LTD (FORMERLY MATRIX LABORATORIES) | I25: Direct Drop | J25: CIP | K25: Air | L25: 39918 | M25: 40077 | N25: 40077 | O25: 40077 | P25: Lamivudine/Nevirapine/Zidovudine 150/200/300mg, tablets, 60 Tabs | Q25: Lamivudine/Nevirapine/Zidovudine | R25: Generic | S25: 150/300/200mg | T25: Tablet - FDC | U25: 60 | V25: 54432 | W25: 641753.28 | X25: 11.79 | Y25: 0.2 | Z25: 7278 | AA25: 61925.7 | AB25: 1 | AC25: 2009 | AE25: 10886.4
B26: 3955 | C26: SCMS-157 | D26: ASN-127 | E26: Uganda | F26: ARV | G26: Adult | H26: Aurobindo Pharma Limited | I26: Direct Drop | J26: EXW | K26: Air | M26: 39072 | N26: 39072 | O26: 39072 | P26: Lamivudine/Zidovudine 150/300mg, tablets, 60 Tabs | Q26: Lamivudine/Zidovudine | R26: Generic | S26: 150/300mg | T26: Tablet - FDC | U26: 60 | V26: 5080 | W26: 55880 | X26: 11 | Y26: 0.18 | Z26: 1172 | AA26: 5595.44 | AB26: 1 | AC26: 2006 | AE26: 914.4
B27: 4193 | C27: SCMS-14221 | D27: ASN-1595 | E27: Rwanda | F27: ARV | G27: Adult | H27: CIPLA LIMITED | I27: Direct Drop | J27: CIP | K27: Air | L27: 39407 | M27: 39566 | N27: 39560 | O27: 39560 | P27: Lamivudine/Nevirapine/Stavudine 150/200/30mg, tablets, 60 Tabs | Q27: Lamivudine/Nevirapine/Stavudine | R27: Generic | S27: 150/200/30mg | T27: Tablet - FDC | U27: 60 | V27: 38784 | W27: 271488 | X27: 7 | Y27: 0.12 | Z27: 4124 | AA27: 10500 | AB27: 1 | AC27: 2008 | AE27: 4654.08
B28: 4567 | C28: SCMS-23611 | D28: ASN-2727 | E28: Tanzania | F28: ARV | G28: Adult | H28: BRISTOL-MYERS SQUIBB | I28: Direct Drop | J28: CIP | K28: Air | L28: 39583 | M28: 39755 | N28: 39755 | O28: 39755 | P28: Didanosine EC 400mg [Videx EC], delayed-release capsules, Blister 3 x 10 Caps | Q28: Didanosine EC | R28: Videx EC | S28: 400mg | T28: Delayed-release capsules - blister | U28: 30 | V28: 2597 | W28: 61470.99 | X28: 23.67 | Y28: 0.79 | AB28: 1 | AC28: 2008 | AE28: 2051.63
B29: 4709 | C29: SCMS-30310 | D29: ASN-3505 | E29: Rwanda | F29: ARV | G29: Adult | H29: CIPLA LIMITED | I29: Direct Drop | J29: CIP | K29: Air | L29: 39742 | M29: 39882 | N29: 39882 | O29: 39882 | P29: Lamivudine/Zidovudine 150/300mg, tablets, 60 Tabs | Q29: Lamivudine/Zidovudine | R29: Generic | S29: 150/300mg | T29: Tablet - FDC | U29: 60 | V29: 18560 | W29: 168896 | X29: 9.1 | Y29: 0.15 | Z29: 1698 | AA29: 16414.22 | AB29: 1 | AC29: 2009 | AE29: 2784
B30: 4824 | C30: SCMS-34690 | D30: ASN-3853 | E30: Tanzania | F30: ARV | G30: Adult | H30: MERCK SHARP & DOHME IDEA GMBH (FORMALLY MERCK SHARP & DOHME B.V.) | I30: Direct Drop | J30: CIP | K30: Air | L30: 39812 | M30: 39979 | N30: 39979 | O30: 39979 | P30: Efavirenz/Emtricitabine/Tenofovir Disoproxil Fumarate 600/200/300mg [Atripla], tablets, 30 Tabs | Q30: Efavirenz/Emtricitabine/Tenofovir Disoproxil Fumarate | R30: Atripla | S30: 600/200/300mg | T30: Tablet - FDC | U30: 30 | V30: 24963 | W30: 1258135.2 | X30: 50.4 | Y30: 1.68 | Z30: 2462 | AA30: 3451.41 | AB30: 1 | AC30: 2009 | AE30: 41937.84
B31: 4949 | C31: SCMS-38410 | D31: ASN-4381 | E31: Tanzania | F31: ARV | G31: Adult | H31: ABBVIE LOGISTICS (FORMERLY ABBOTT LOGISTICS BV) | I31: Direct Drop | J31: FCA | K31: Air | L31: 39849 | M31: 40036 | N31: 40036 | O31: 40036 | P31: Lopinavir/Ritonavir 200/50mg [Aluvia], tablets, 120 Tabs | Q31: Lopinavir/Ritonavir | R31: Aluvia | S31: 200/50mg | T31: Tablet | U31: 120 | V31: 10680 | W31: 438948 | X31: 41.1 | Y31: 0.34 | Z31: 2724 | AA31: 12620.12 | AB31: 1 | AC31: 2009 | AE31: 3631.2
B32: 5113 | C32: SCMS-43900 | D32: ASN-4553 | E32: Rwanda | F32: ARV | G32: Adult | H32: HETERO LABS LIMITED | I32: Direct Drop | J32: CIP | K32: Air | L32: 40009 | M32: 40037 | N32: 40037 | O32: 40037 | P32: Efavirenz 600mg, tablets, 30 Tabs | Q32: Efavirenz | R32: Generic | S32: 600mg | T32: Tablet | U32: 30 | V32: 28034 | W32: 195677.32 | X32: 6.98 | Y32: 0.23 | Z32: 2268 | AA32: 19023.36 | AB32: 1 | AC32: 2009 | AE32: 6447.82
B33: 5175 | C33: SCMS-46500 | D33: ASN-4223 | E33: Tanzania | F33: ARV | G33: Adult | H33: Hoffmann-La Roche ltd Basel | I33: Direct Drop | J33: FCA | K33: Air | L33: 39961 | M33: 40024 | N33: 40024 | O33: 40024 | P33: Saquinavir 200mg [Invirase], capsules, 270 Caps | Q33: Saquinavir | R33: Invirase | S33: 200mg | T33: Capsule | U33: 270 | V33: 820 | W33: 73074.13 | X33: 89.11 | Y33: 0.33 | Z33: 424 | AA33: 3310.89 | AB33: 1 | AC33: 2009 | AE33: 270.6
B34: 5277 | C34: SCMS-159 | D34: ASN-125 | E34: Uganda | F34: ARV | G34: Adult | H34: SUN PHARMACEUTICAL INDUSTRIES LTD (RANBAXY LABORATORIES LIMITED) | I34: Direct Drop | J34: EXW | K34: Air | M34: 39073 | N34: 39073 | O34: 39073 | P34: Lamivudine 150mg, tablets, 60 Tabs | Q34: Lamivudine | R34: Generic | S34: 150mg | T34: Tablet | U34: 60 | V34: 6349 | W34: 21269.15 | X34: 3.35 | Y34: 0.06 | Z34: 369 | AA34: 2623.49 | AB34: 1 | AC34: 2006 | AE34: 380.94
B35: 5905 | C35: SCMS-26640 | D35: ASN-2408 | E35: Tanzania | F35: ARV | G35: Pediatric | H35: GLAXOSMITHKLINE EXPORT LIMITED | I35: Direct Drop | J35: CIP | K35: Air | L35: 39633 | M35: 39699 | N35: 39699 | O35: 39699 | P35: Abacavir 20mg/ml [Ziagen], oral solution, Bottle, 240 ml | Q35: Abacavir | R35: Ziagen | S35: 20mg/ml | T35: Oral solution | U35: 240 | V35: 132 | W35: 1990.56 | X35: 15.08 | Y35: 0.06 | Z35: 65 | AA35: 633 | AB35: 1 | AC35: 2008 | AE35: 7.92
B36: 6621 | C36: SCMS-157 | D36: ASN-127 | E36: Uganda | F36: ARV | G36: Adult | H36: Aurobindo Pharma Limited | I36: Direct Drop | J36: EXW | K36: Air | M36: 39072 | N36: 39072 | O36: 39072 | P36: Stavudine 30mg, capsules, 60 Caps | Q36: Stavudine | R36: Generic | S36: 30mg | T36: Capsule | U36: 60 | V36: 6349 | W36: 12380.55 | X36: 1.95 | Y36: 0.03 | AB36: 1 | AC36: 2006 | AE36: 190.47
B37: 6622 | C37: SCMS-160 | D37: ASN-124 | E37: Uganda | F37: ARV | G37: Adult | H37: STRIDES ARCOLAB LIMITED | I37: Direct Drop | J37: EXW | K37: Air | M37: 39084 | N37: 39084 | O37: 39084 | P37: Nevirapine 200mg, tablets, 60 Tabs | Q37: Nevirapine | R37: Generic | S37: 200mg | T37: Tablet | U37: 60 | V37: 6349 | W37: 21586.6 | X37: 3.4 | Y37: 0.06 | Z37: 355 | AA37: 3181.2 | AB37: 1 | AC37: 2007 | AE37: 380.94
B38: 6705 | C38: SCMS-800 | D38: ASN-719 | E38: Rwanda | F38: ARV | G38: Pediatric | H38: BRISTOL-MYERS SQUIBB | I38: Direct Drop | J38: CIP | K38: Air | L38: 39280 | M38: 39339 | N38: 39339 | O38: 39339 | P38: Didanosine 50mg [Videx], chewable tablets, 60 Tabs | Q38: Didanosine | R38: Videx | S38: 50mg | T38: Chewable/dispersible tablet | U38: 60 | V38: 182 | W38: 1729 | X38: 9.5 | Y38: 0.16 | Z38: 40 | AA38: 86.4 | AB38: 1 | AC38: 2007 | AE38: 29.12
B39: 6837 | C39: SCMS-13900 | D39: ASN-990 | E39: Rwanda | F39: ARV | G39: Adult | H39: ASPEN PHARMACARE | I39: Direct Drop | J39: EXW | K39: Air | L39: 39398 | M39: 39475 | N39: 39475 | O39: 39475 | P39: Tenofovir Disoproxil Fumarate 300mg [Viread], tablets, 30 Tabs | Q39: Tenofovir Disoproxil Fumarate | R39: Viread | S39: 300mg | T39: Tablet | U39: 30 | V39: 84 | W39: 0.84 | X39: 0.01 | Y39: 0 | AB39: 1 | AC39: 2008 | AE39: 0
B40: 6848 | C40: SCMS-14221 | D40: ASN-1594 | E40: Rwanda | F40: ARV | G40: Adult | H40: CIPLA LIMITED | I40: Direct Drop | J40: CIP | K40: Air | L40: 39407 | M40: 39566 | N40: 39560 | O40: 39560 | P40: Lamivudine/Nevirapine/Stavudine 150/200/30mg, tablets, 60 Tabs | Q40: Lamivudine/Nevirapine/Stavudine | R40: Generic | S40: 150/200/30mg | T40: Tablet - FDC | U40: 60 | V40: 34576 | W40: 242032 | X40: 7 | Y40: 0.12 | Z40: 3656 | AA40: 10500 | AB40: 1 | AC40: 2008 | AE40: 4149.12
B41: 6849 | C41: SCMS-14221 | D41: ASN-1596 | E41: Rwanda | F41: ARV | G41: Adult | H41: CIPLA LIMITED | I41: Direct Drop | J41: CIP | K41: Air | L41: 39407 | M41: 39566 | N41: 39566 | O41: 39566 | P41: Lamivudine/Nevirapine/Stavudine 150/200/30mg, tablets, 60 Tabs | Q41: Lamivudine/Nevirapine/Stavudine | R41: Generic | S41: 150/200/30mg | T41: Tablet - FDC | U41: 60 | V41: 16640 | W41: 116480 | X41: 7 | Y41: 0.12 | Z41: 1766 | AA41: 10500 | AB41: 1 | AC41: 2008 | AE41: 1996.8
...

Sheet Calculation
N1: 2.2 On-time Delivery Rate (OTD%)
B2: 1. ARV value by Region and Supply method | F2: Commodity Value | G2: =SUM(tblARV[Line Item Value]) -> 2.8264668e+08 | Q2: 2.4 Comparative Delivery Reliability | X2: 2. Reasonable Procurement Cost
N3: Total Delivery | O3: =COUNTA($F$20:$F$1349) -> 1330 | Q3: 2.4.1 by Country
B4: Sum of Line Items | G4: Commodity Value by Fulfillment Chanel | N4: Count of On-time | O4: =COUNTIF($F$20:$F$1349,"On-time") -> 1156 | Y4: Item Description | Z4: Lamivudine/Nevirapine/Zidovudine 150/200/300mg, tablets, 60 Tabs
B5: 'Country | C5: Direct Drop | D5: From RDC | E5: Total | G5: Direct Drop | H5: =+C13 -> 84170273 | N5: Count of Late | O5: =COUNTIF($F$20:$F$1349,"Late") -> 174 | Q5: Row Labels | R5: Count of ASN/DN # | S5: Sum of On_time_flag | T5: Count of On_time_flag2
B6: Burundi | D6: 1271711 | E6: 1271711 | G6: From RDC | H6: =+D13 -> 1.9847641e+08 | N6: OTD Rate | O6: =O4/$O$3 -> 0.86917293 | Q6: Burundi | R6: 72 | S6: 34 | T6: 72 | Y6: Year | Z6: USD Per Pack
B7: Ethiopia | C7: 2939836.8 | D7: 10663658 | E7: 13603494 | G7: Total | H7: =SUM(H5:H6) -> 2.8264668e+08 | N7: OTD Rate Chanel | Q7: Ethiopia | R7: 141 | S7: 129 | T7: 141 | Y7: 2007 | Z7: 18.430108
B8: Kenya | D8: 7878.7 | E8: 7878.7 | N8: From RDC | O8: =COUNTIFS($F$20:$F$1349,"On-time",$H$20:$H$1349,$N8)/COUNTIF($H$20:$H$1349,$N8) -> 0.81950673 | Q8: Kenya | R8: 4 | S8: 4 | T8: 4 | Y8: 2008 | Z8: 11.996223
B9: Rwanda | C9: 35811698 | D9: 26324471 | E9: 62136169 | N9: Direct Drop | O9: =COUNTIFS($F$20:$F$1349,"On-time",$H$20:$H$1349,$N9)/COUNTIF($H$20:$H$1349,$N9) -> 0.97031963 | Q9: Rwanda | R9: 349 | S9: 315 | T9: 349 | Y9: 2009 | Z9: 11.578117
B10: Tanzania | C10: 30408879 | D10: 84151677 | E10: 1.1456056e+08 | Q10: South Sudan | R10: 52 | S10: 42 | T10: 52 | Y10: 2010 | Z10: 11.238156
B11: Uganda | C11: 15004699 | D11: 74857939 | E11: 89862638 | N11: 2.3 Average Delay Severity and Consistency | Q11: Tanzania | R11: 397 | S11: 336 | T11: 397 | Y11: 2011 | Z11: 11.203822
B12: South Sudan | C12: 5160.25 | D12: 1199076.5 | E12: 1204236.7 | N12: Average Delay | O12: =AVERAGEIF($E$20:$E$1349,">0") -> 21.488506 | Q12: Uganda | R12: 738 | S12: 641 | T12: 738 | Y12: 2012 | Z12: 10.477873
B13: Total | C13: 84170273 | D13: 1.9847641e+08 | E13: 2.8264668e+08 | N13: Max Delay | O13: =_xlfn.MAXIFS($E$20:$E$1349,$E$20:$E$1349,">0") -> 280 | Q13: Grand Total | R13: 1753 | S13: 1501 | T13: 1753 | Y13: 2013 | Z13: 8.3026637
N14: Min Delay | O14: =_xlfn.MINIFS($E$20:$E$1349,$E$20:$E$1349,">0") -> 1 | Y14: 2014 | Z14: 8.1930147
N15: Median Delay | O15: {=MEDIAN(_xlfn._xlws.FILTER(E$20:$E$1349,(E$20:$E$1349)>0))} -> 12 | Y15: 2015 | Z15: 7.9930262
B16: 2. ARV Delivery Reliability and Consistency | N16: STD.V Delpay | O16: {=_xlfn.STDEV.S(_xlfn._xlws.FILTER(E$20:$E$1349,(E$20:$E$1349)>0))} -> 30.303997 | Y16: Grand Total | Z16: 9.5359766
B18: 2.1 Delivery Variance | N18: 2.4 Comparative Delivery Reliability
B19: Delivery | C19: Scheduled date | D19: Actual Date | E19: Variance | F19: Delivery Status | G19: Country | H19: Fulfill Via | I19: Vendor | N19: 2.4.1 by Country | Q19: 1 | R19: {=INDEX(S19:S21,Q19)} -> All | S19: All
B20: ASN-10070 | C20: 40660 | D20: 40660 | E20: 0 | F20: =IF($E20<=0,"On-time","Late") -> On-time | G20: =_xlfn.XLOOKUP($B20,tblARV[ASN/DN '#],tblARV[Country],"Not found") -> Rwanda | H20: =_xlfn.XLOOKUP($B20,tblARV[ASN/DN '#],tblARV[Fulfill Via],"Not found") -> Direct Drop | I20: =_xlfn.XLOOKUP($B20,tblARV[ASN/DN '#],tblARV[Vendor],"Not found") -> MYLAN LABORATORIES LTD (FORMERLY MATRIX LABORATORIES) | S20: {=_xlfn.UNIQUE(tblARV[Fulfill Via])} -> Direct Drop
B21: ASN-10140 | C21: 40641 | D21: 40641 | E21: 0 | F21: =IF($E21<=0,"On-time","Late") -> On-time | G21: =_xlfn.XLOOKUP(B21,tblARV[ASN/DN '#],tblARV[Country],"Not found") -> Rwanda | H21: =_xlfn.XLOOKUP($B21,tblARV[ASN/DN '#],tblARV[Fulfill Via],"Not found") -> Direct Drop | I21: =_xlfn.XLOOKUP($B21,tblARV[ASN/DN '#],tblARV[Vendor],"Not found") -> Aurobindo Pharma Limited | S21: From RDC
B22: ASN-10317 | C22: 40694 | D22: 40694 | E22: 0 | F22: =IF($E22<=0,"On-time","Late") -> On-time | G22: =_xlfn.XLOOKUP(B22,tblARV[ASN/DN '#],tblARV[Country],"Not found") -> Rwanda | H22: =_xlfn.XLOOKUP($B22,tblARV[ASN/DN '#],tblARV[Fulfill Via],"Not found") -> Direct Drop | I22: =_xlfn.XLOOKUP($B22,tblARV[ASN/DN '#],tblARV[Vendor],"Not found") -> HETERO LABS LIMITED
B23: ASN-10338 | C23: 40631 | D23: 40631 | E23: 0 | F23: =IF($E23<=0,"On-time","Late") -> On-time | G23: =_xlfn.XLOOKUP(B23,tblARV[ASN/DN '#],tblARV[Country],"Not found") -> Uganda | H23: =_xlfn.XLOOKUP($B23,tblARV[ASN/DN '#],tblARV[Fulfill Via],"Not found") -> Direct Drop | I23: =_xlfn.XLOOKUP($B23,tblARV[ASN/DN '#],tblARV[Vendor],"Not found") -> ASPEN PHARMACARE
B24: ASN-1039 | C24: 39406 | D24: 39440 | E24: 34 | F24: =IF($E24<=0,"On-time","Late") -> Late | G24: =_xlfn.XLOOKUP(B24,tblARV[ASN/DN '#],tblARV[Country],"Not found") -> Ethiopia | H24: =_xlfn.XLOOKUP($B24,tblARV[ASN/DN '#],tblARV[Fulfill Via],"Not found") -> Direct Drop | I24: =_xlfn.XLOOKUP($B24,tblARV[ASN/DN '#],tblARV[Vendor],"Not found") -> Aurobindo Pharma Limited | N24: Country | O24: On-time | P24: Late | Q24: Total | R24: OTD% | S24: LTD%
B25: ASN-10455 | C25: 40652 | D25: 40652 | E25: 0 | F25: =IF($E25<=0,"On-time","Late") -> On-time | G25: =_xlfn.XLOOKUP(B25,tblARV[ASN/DN '#],tblARV[Country],"Not found") -> Uganda | H25: =_xlfn.XLOOKUP($B25,tblARV[ASN/DN '#],tblARV[Fulfill Via],"Not found") -> Direct Drop | I25: =_xlfn.XLOOKUP($B25,tblARV[ASN/DN '#],tblARV[Vendor],"Not found") -> MERCK SHARP & DOHME IDEA GMBH (FORMALLY MERCK SHARP & DOHME B.V.) | N25: Uganda | O25: =COUNTIFS($F$20:$F$1349,$O$24,$G$20:$G$1349,$N25) -> 477 | P25: =CHOOSE($Q$19,COUNTIFS($F$20:$F$1349,P$24,$G$20:$G$1349,$N25), COUNTIFS($F$20:$F$1349,P$24,$G$20:$G$1349,$N25,$H$20:$H$1349,$R$19), COUNTIFS($F$20:$F$1349,P$24,$G$20:$G$1349,$N25,$H$20:$H$1349,$R$19)) -> 68 | Q25: =SUM(O25:P25) -> 545 | R25: =+O25/Q25 -> 0.87522936 | S25: =P25/Q25 -> 0.12477064
B26: ASN-1066 | C26: 39450 | D26: 39450 | E26: 0 | F26: =IF($E26<=0,"On-time","Late") -> On-time | G26: =_xlfn.XLOOKUP(B26,tblARV[ASN/DN '#],tblARV[Country],"Not found") -> Rwanda | H26: =_xlfn.XLOOKUP($B26,tblARV[ASN/DN '#],tblARV[Fulfill Via],"Not found") -> Direct Drop | I26: =_xlfn.XLOOKUP($B26,tblARV[ASN/DN '#],tblARV[Vendor],"Not found") -> Aurobindo Pharma Limited | N26: Tanzania | O26: =COUNTIFS($F$20:$F$1349,$O$24,$G$20:$G$1349,$N26) -> 268 | P26: =CHOOSE($Q$19,COUNTIFS($F$20:$F$1349,P$24,$G$20:$G$1349,$N26), COUNTIFS($F$20:$F$1349,P$24,$G$20:$G$1349,$N26,$H$20:$H$1349,$R$19), COUNTIFS($F$20:$F$1349,P$24,$G$20:$G$1349,$N26,$H$20:$H$1349,$R$19)) -> 45 | Q26: =SUM(O26:P26) -> 313 | R26: =+O26/Q26 -> 0.85623003 | S26: =P26/Q26 -> 0.14376997
B27: ASN-10663 | C27: 40658 | D27: 40658 | E27: 0 | F27: =IF($E27<=0,"On-time","Late") -> On-time | G27: =_xlfn.XLOOKUP(B27,tblARV[ASN/DN '#],tblARV[Country],"Not found") -> Rwanda | H27: =_xlfn.XLOOKUP($B27,tblARV[ASN/DN '#],tblARV[Fulfill Via],"Not found") -> Direct Drop | I27: =_xlfn.XLOOKUP($B27,tblARV[ASN/DN '#],tblARV[Vendor],"Not found") -> Aurobindo Pharma Limited | N27: South Sudan | O27: =COUNTIFS($F$20:$F$1349,$O$24,$G$20:$G$1349,$N27) -> 19 | P27: =CHOOSE($Q$19,COUNTIFS($F$20:$F$1349,P$24,$G$20:$G$1349,$N27), COUNTIFS($F$20:$F$1349,P$24,$G$20:$G$1349,$N27,$H$20:$H$1349,$R$19), COUNTIFS($F$20:$F$1349,P$24,$G$20:$G$1349,$N27,$H$20:$H$1349,$R$19)) -> 5 | Q27: =SUM(O27:P27) -> 24 | R27: =+O27/Q27 -> 0.79166667 | S27: =P27/Q27 -> 0.20833333
B28: ASN-10666 | C28: 40667 | D28: 40667 | E28: 0 | F28: =IF($E28<=0,"On-time","Late") -> On-time | G28: =_xlfn.XLOOKUP(B28,tblARV[ASN/DN '#],tblARV[Country],"Not found") -> Ethiopia | H28: =_xlfn.XLOOKUP($B28,tblARV[ASN/DN '#],tblARV[Fulfill Via],"Not found") -> Direct Drop | I28: =_xlfn.XLOOKUP($B28,tblARV[ASN/DN '#],tblARV[Vendor],"Not found") -> Aurobindo Pharma Limited | N28: Rwanda | O28: =COUNTIFS($F$20:$F$1349,$O$24,$G$20:$G$1349,$N28) -> 276 | P28: =CHOOSE($Q$19,COUNTIFS($F$20:$F$1349,P$24,$G$20:$G$1349,$N28), COUNTIFS($F$20:$F$1349,P$24,$G$20:$G$1349,$N28,$H$20:$H$1349,$R$19), COUNTIFS($F$20:$F$1349,P$24,$G$20:$G$1349,$N28,$H$20:$H$1349,$R$19)) -> 27 | Q28: =SUM(O28:P28) -> 303 | R28: =+O28/Q28 -> 0.91089109 | S28: =P28/Q28 -> 0.089108911
B29: ASN-1067 | C29: 39450 | D29: 39450 | E29: 0 | F29: =IF($E29<=0,"On-time","Late") -> On-time | G29: =_xlfn.XLOOKUP(B29,tblARV[ASN/DN '#],tblARV[Country],"Not found") -> Rwanda | H29: =_xlfn.XLOOKUP($B29,tblARV[ASN/DN '#],tblARV[Fulfill Via],"Not found") -> Direct Drop | I29: =_xlfn.XLOOKUP($B29,tblARV[ASN/DN '#],tblARV[Vendor],"Not found") -> Aurobindo Pharma Limited | N29: Kenya | O29: =COUNTIFS($F$20:$F$1349,$O$24,$G$20:$G$1349,$N29) -> 3 | P29: =CHOOSE($Q$19,COUNTIFS($F$20:$F$1349,P$24,$G$20:$G$1349,$N29), COUNTIFS($F$20:$F$1349,P$24,$G$20:$G$1349,$N29,$H$20:$H$1349,$R$19), COUNTIFS($F$20:$F$1349,P$24,$G$20:$G$1349,$N29,$H$20:$H$1349,$R$19)) -> 0 | Q29: =SUM(O29:P29) -> 3 | R29: =+O29/Q29 -> 1 | S29: =P29/Q29 -> 0
B30: ASN-10790 | C30: 40711 | D30: 40711 | E30: 0 | F30: =IF($E30<=0,"On-time","Late") -> On-time | G30: =_xlfn.XLOOKUP(B30,tblARV[ASN/DN '#],tblARV[Country],"Not found") -> Rwanda | H30: =_xlfn.XLOOKUP($B30,tblARV[ASN/DN '#],tblARV[Fulfill Via],"Not found") -> Direct Drop | I30: =_xlfn.XLOOKUP($B30,tblARV[ASN/DN '#],tblARV[Vendor],"Not found") -> HETERO LABS LIMITED | N30: Ethiopia | O30: =COUNTIFS($F$20:$F$1349,$O$24,$G$20:$G$1349,$N30) -> 96 | P30: =CHOOSE($Q$19,COUNTIFS($F$20:$F$1349,P$24,$G$20:$G$1349,$N30), COUNTIFS($F$20:$F$1349,P$24,$G$20:$G$1349,$N30,$H$20:$H$1349,$R$19), COUNTIFS($F$20:$F$1349,P$24,$G$20:$G$1349,$N30,$H$20:$H$1349,$R$19)) -> 11 | Q30: =SUM(O30:P30) -> 107 | R30: =+O30/Q30 -> 0.89719626 | S30: =P30/Q30 -> 0.10280374
B31: ASN-10811 | C31: 40721 | D31: 40721 | E31: 0 | F31: =IF($E31<=0,"On-time","Late") -> On-time | G31: =_xlfn.XLOOKUP(B31,tblARV[ASN/DN '#],tblARV[Country],"Not found") -> Tanzania | H31: =_xlfn.XLOOKUP($B31,tblARV[ASN/DN '#],tblARV[Fulfill Via],"Not found") -> Direct Drop | I31: =_xlfn.XLOOKUP($B31,tblARV[ASN/DN '#],tblARV[Vendor],"Not found") -> LAWRENCE LABORATORIES (SUBSIDIARY OF BRISTOL MYERS SQUIBB) | N31: Burundi | O31: =COUNTIFS($F$20:$F$1349,$O$24,$G$20:$G$1349,$N31) -> 17 | P31: =CHOOSE($Q$19,COUNTIFS($F$20:$F$1349,P$24,$G$20:$G$1349,$N31), COUNTIFS($F$20:$F$1349,P$24,$G$20:$G$1349,$N31,$H$20:$H$1349,$R$19), COUNTIFS($F$20:$F$1349,P$24,$G$20:$G$1349,$N31,$H$20:$H$1349,$R$19)) -> 18 | Q31: =SUM(O31:P31) -> 35 | R31: =+O31/Q31 -> 0.48571429 | S31: =P31/Q31 -> 0.51428571
B32: ASN-11005 | C32: 40738 | D32: 40738 | E32: 0 | F32: =IF($E32<=0,"On-time","Late") -> On-time | G32: =_xlfn.XLOOKUP(B32,tblARV[ASN/DN '#],tblARV[Country],"Not found") -> Tanzania | H32: =_xlfn.XLOOKUP($B32,tblARV[ASN/DN '#],tblARV[Fulfill Via],"Not found") -> Direct Drop | I32: =_xlfn.XLOOKUP($B32,tblARV[ASN/DN '#],tblARV[Vendor],"Not found") -> LAWRENCE LABORATORIES (SUBSIDIARY OF BRISTOL MYERS SQUIBB)
B33: ASN-11009 | C33: 40694 | D33: 40694 | E33: 0 | F33: =IF($E33<=0,"On-time","Late") -> On-time | G33: =_xlfn.XLOOKUP(B33,tblARV[ASN/DN '#],tblARV[Country],"Not found") -> Uganda | H33: =_xlfn.XLOOKUP($B33,tblARV[ASN/DN '#],tblARV[Fulfill Via],"Not found") -> Direct Drop | I33: =_xlfn.XLOOKUP($B33,tblARV[ASN/DN '#],tblARV[Vendor],"Not found") -> ASPEN PHARMACARE
B34: ASN-11026 | C34: 40696 | D34: 40696 | E34: 0 | F34: =IF($E34<=0,"On-time","Late") -> On-time | G34: =_xlfn.XLOOKUP(B34,tblARV[ASN/DN '#],tblARV[Country],"Not found") -> Uganda | H34: =_xlfn.XLOOKUP($B34,tblARV[ASN/DN '#],tblARV[Fulfill Via],"Not found") -> Direct Drop | I34: =_xlfn.XLOOKUP($B34,tblARV[ASN/DN '#],tblARV[Vendor],"Not found") -> ASPEN PHARMACARE
B35: ASN-11156 | C35: 40722 | D35: 40722 | E35: 0 | F35: =IF($E35<=0,"On-time","Late") -> On-time | G35: =_xlfn.XLOOKUP(B35,tblARV[ASN/DN '#],tblARV[Country],"Not found") -> Ethiopia | H35: =_xlfn.XLOOKUP($B35,tblARV[ASN/DN '#],tblARV[Fulfill Via],"Not found") -> Direct Drop | I35: =_xlfn.XLOOKUP($B35,tblARV[ASN/DN '#],tblARV[Vendor],"Not found") -> Aurobindo Pharma Limited | N35: 2.4.3 by Vendor
B36: ASN-11253 | C36: 40725 | D36: 40725 | E36: 0 | F36: =IF($E36<=0,"On-time","Late") -> On-time | G36: =_xlfn.XLOOKUP(B36,tblARV[ASN/DN '#],tblARV[Country],"Not found") -> Ethiopia | H36: =_xlfn.XLOOKUP($B36,tblARV[ASN/DN '#],tblARV[Fulfill Via],"Not found") -> Direct Drop | I36: =_xlfn.XLOOKUP($B36,tblARV[ASN/DN '#],tblARV[Vendor],"Not found") -> MYLAN LABORATORIES LTD (FORMERLY MATRIX LABORATORIES) | N36: Vendor | O36: On-time | P36: Late | Q36: Total | R36: OTD% | S36: LTD%
B37: ASN-11275 | C37: 40807 | D37: 40807 | E37: 0 | F37: =IF($E37<=0,"On-time","Late") -> On-time | G37: =_xlfn.XLOOKUP(B37,tblARV[ASN/DN '#],tblARV[Country],"Not found") -> Ethiopia | H37: =_xlfn.XLOOKUP($B37,tblARV[ASN/DN '#],tblARV[Fulfill Via],"Not found") -> Direct Drop | I37: =_xlfn.XLOOKUP($B37,tblARV[ASN/DN '#],tblARV[Vendor],"Not found") -> Aurobindo Pharma Limited | N37: {=+_xlfn.UNIQUE(I20:I1349)} -> MYLAN LABORATORIES LTD (FORMERLY MATRIX LABORATORIES) | O37: =COUNTIFS($F$20:$F$1349,O$36,$I$20:$I$1349,$N37) -> 63 | P37: =COUNTIFS($F$20:$F$1349,P$36,$I$20:$I$1349,$N37) -> 0 | Q37: =SUM(O37:P37) -> 63 | R37: =+O37/Q37 -> 1 | S37: =P37/Q37 -> 0
B38: ASN-11530 | C38: 40746 | D38: 40746 | E38: 0 | F38: =IF($E38<=0,"On-time","Late") -> On-time | G38: =_xlfn.XLOOKUP(B38,tblARV[ASN/DN '#],tblARV[Country],"Not found") -> Uganda | H38: =_xlfn.XLOOKUP($B38,tblARV[ASN/DN '#],tblARV[Fulfill Via],"Not found") -> Direct Drop | I38: =_xlfn.XLOOKUP($B38,tblARV[ASN/DN '#],tblARV[Vendor],"Not found") -> ASPEN PHARMACARE | N38: Aurobindo Pharma Limited | O38: =COUNTIFS($F$20:$F$1349,O$36,$I$20:$I$1349,$N38) -> 92 | P38: =COUNTIFS($F$20:$F$1349,P$36,$I$20:$I$1349,$N38) -> 13 | Q38: =SUM(O38:P38) -> 105 | R38: =+O38/Q38 -> 0.87619048 | S38: =P38/Q38 -> 0.12380952
B39: ASN-11548 | C39: 40833 | D39: 40833 | E39: 0 | F39: =IF($E39<=0,"On-time","Late") -> On-time | G39: =_xlfn.XLOOKUP(B39,tblARV[ASN/DN '#],tblARV[Country],"Not found") -> Rwanda | H39: =_xlfn.XLOOKUP($B39,tblARV[ASN/DN '#],tblARV[Fulfill Via],"Not found") -> Direct Drop | I39: =_xlfn.XLOOKUP($B39,tblARV[ASN/DN '#],tblARV[Vendor],"Not found") -> HETERO LABS LIMITED | N39: HETERO LABS LIMITED | O39: =COUNTIFS($F$20:$F$1349,O$36,$I$20:$I$1349,$N39) -> 41 | P39: =COUNTIFS($F$20:$F$1349,P$36,$I$20:$I$1349,$N39) -> 0 | Q39: =SUM(O39:P39) -> 41 | R39: =+O39/Q39 -> 1 | S39: =P39/Q39 -> 0
B40: ASN-11623 | C40: 40815 | D40: 40815 | E40: 0 | F40: =IF($E40<=0,"On-time","Late") -> On-time | G40: =_xlfn.XLOOKUP(B40,tblARV[ASN/DN '#],tblARV[Country],"Not found") -> Tanzania | H40: =_xlfn.XLOOKUP($B40,tblARV[ASN/DN '#],tblARV[Fulfill Via],"Not found") -> Direct Drop | I40: =_xlfn.XLOOKUP($B40,tblARV[ASN/DN '#],tblARV[Vendor],"Not found") -> EMCURE PHARMACEUTICALS LTD | N40: ASPEN PHARMACARE | O40: =COUNTIFS($F$20:$F$1349,O$36,$I$20:$I$1349,$N40) -> 29 | P40: =COUNTIFS($F$20:$F$1349,P$36,$I$20:$I$1349,$N40) -> 0 | Q40: =SUM(O40:P40) -> 29 | R40: =+O40/Q40 -> 1 | S40: =P40/Q40 -> 0
B41: ASN-11688 | C41: 40780 | D41: 40780 | E41: 0 | F41: =IF($E41<=0,"On-time","Late") -> On-time | G41: =_xlfn.XLOOKUP(B41,tblARV[ASN/DN '#],tblARV[Country],"Not found") -> Ethiopia | H41: =_xlfn.XLOOKUP($B41,tblARV[ASN/DN '#],tblARV[Fulfill Via],"Not found") -> Direct Drop | I41: =_xlfn.XLOOKUP($B41,tblARV[ASN/DN '#],tblARV[Vendor],"Not found") -> Aurobindo Pharma Limited | N41: MERCK SHARP & DOHME IDEA GMBH (FORMALLY MERCK SHARP & DOHME B.V.) | O41: =COUNTIFS($F$20:$F$1349,O$36,$I$20:$I$1349,$N41) -> 19 | P41: =COUNTIFS($F$20:$F$1349,P$36,$I$20:$I$1349,$N41) -> 0 | Q41: =SUM(O41:P41) -> 19 | R41: =+O41/Q41 -> 1 | S41: =P41/Q41 -> 0
...

Sheet Dashboard
B6: 1. Timely Delivery - Delivery Reliability by Country | J6: 1. Timely Delivery - Delivery Reliability By Fulfillment Channel
B8: Fulfillment Channel:
B10: =+Calculation!N24 -> Country | C10: =+Calculation!O24 -> On-time | D10: =+Calculation!P24 -> Late | E10: =+Calculation!Q24 -> Total | F10: =+Calculation!R24 -> OTD%
B11: =Calculation!N25 -> Uganda | C11: =Calculation!O25 -> 477 | D11: =Calculation!P25 -> 68 | E11: =Calculation!Q25 -> 545 | F11: =+G11 -> 0.87522936 | G11: =Calculation!R25 -> 0.87522936
B12: =Calculation!N26 -> Tanzania | C12: =Calculation!O26 -> 268 | D12: =Calculation!P26 -> 45 | E12: =Calculation!Q26 -> 313 | F12: =+G12 -> 0.85623003 | G12: =Calculation!R26 -> 0.85623003
B13: =Calculation!N27 -> South Sudan | C13: =Calculation!O27 -> 19 | D13: =Calculation!P27 -> 5 | E13: =Calculation!Q27 -> 24 | F13: =+G13 -> 0.79166667 | G13: =Calculation!R27 -> 0.79166667
B14: =Calculation!N28 -> Rwanda | C14: =Calculation!O28 -> 276 | D14: =Calculation!P28 -> 27 | E14: =Calculation!Q28 -> 303 | F14: =+G14 -> 0.91089109 | G14: =Calculation!R28 -> 0.91089109
B15: =Calculation!N29 -> Kenya | C15: =Calculation!O29 -> 3 | D15: =Calculation!P29 -> 0 | E15: =Calculation!Q29 -> 3 | F15: =+G15 -> 1 | G15: =Calculation!R29 -> 1
B16: =Calculation!N30 -> Ethiopia | C16: =Calculation!O30 -> 96 | D16: =Calculation!P30 -> 11 | E16: =Calculation!Q30 -> 107 | F16: =+G16 -> 0.89719626 | G16: =Calculation!R30 -> 0.89719626
B17: =Calculation!N31 -> Burundi | C17: =Calculation!O31 -> 17 | D17: =Calculation!P31 -> 18 | E17: =Calculation!Q31 -> 35 | F17: =+G17 -> 0.48571429 | G17: =Calculation!R31 -> 0.48571429
B18: Total | C18: =SUM(C11:C17) -> 1156 | D18: =SUM(D11:D17) -> 174 | E18: =SUM(E11:E17) -> 1330 | F18: =C18/$E$18 -> 0.86917293
B20: 2. Procurement Cost - Weighted Pack Price Trend by Product | J20: Reliable - Commodity Value by Fulfillment Channel

Sheet Management Report
B2: ARV SUPPLY CHAIN | MANAGEMENT PERFORMANCE REPORT
B3: East Africa • 2006–2015 • Seven countries • Historical USAID ARV commodity shipment data
B5: TOTAL DELIVERIES | E5: ON-TIME DELIVERY | H5: AVERAGE LATE DELAY | K5: COMMODITY VALUE
B6: 1330 | E6: 0.8692 | H6: 21.49 days | K6: $282.65M
B9: EXECUTIVE ASSESSMENT
B10: The historical ARV distribution records show that 86.92% of evaluated deliveries arrived on or before schedule, but late shipments averaged 21.49 days beyond the scheduled date. Recorded weighted pack prices declined across major ARV presentations, while distribution activity was concentrated in the Regional Distribution Centre (RDC) channel. The immediate management priority is to investigate RDC delivery delays and weak destination-country performance, alongside continued product-specific price monitoring. | C10: The historical ARV distribution records show that 86.92% of evaluated deliveries arrived on or before schedule, but late shipments averaged 21.49 days beyond the scheduled date. Recorded weighted pack prices declined across major ARV presentations, while distribution activity was concentrated in the Regional Distribution Centre (RDC) channel. The immediate management priority is to investigate RDC delivery delays and weak destination-country performance, alongside continued product-specific price monitoring. | D10: The historical ARV distribution records show that 86.92% of evaluated deliveries arrived on or before schedule, but late shipments averaged 21.49 days beyond the scheduled date. Recorded weighted pack prices declined across major ARV presentations, while distribution activity was concentrated in the Regional Distribution Centre (RDC) channel. The immediate management priority is to investigate RDC delivery delays and weak destination-country performance, alongside continued product-specific price monitoring. | E10: The historical ARV distribution records show that 86.92% of evaluated deliveries arrived on or before schedule, but late shipments averaged 21.49 days beyond the scheduled date. Recorded weighted pack prices declined across major ARV presentations, while distribution activity was concentrated in the Regional Distribution Centre (RDC) channel. The immediate management priority is to investigate RDC delivery delays and weak destination-country performance, alongside continued product-specific price monitoring. | F10: The historical ARV distribution records show that 86.92% of evaluated deliveries arrived on or before schedule, but late shipments averaged 21.49 days beyond the scheduled date. Recorded weighted pack prices declined across major ARV presentations, while distribution activity was concentrated in the Regional Distribution Centre (RDC) channel. The immediate management priority is to investigate RDC delivery delays and weak destination-country performance, alongside continued product-specific price monitoring. | G10: The historical ARV distribution records show that 86.92% of evaluated deliveries arrived on or before schedule, but late shipments averaged 21.49 days beyond the scheduled date. Recorded weighted pack prices declined across major ARV presentations, while distribution activity was concentrated in the Regional Distribution Centre (RDC) channel. The immediate management priority is to investigate RDC delivery delays and weak destination-country performance, alongside continued product-specific price monitoring. | H10: The historical ARV distribution records show that 86.92% of evaluated deliveries arrived on or before schedule, but late shipments averaged 21.49 days beyond the scheduled date. Recorded weighted pack prices declined across major ARV presentations, while distribution activity was concentrated in the Regional Distribution Centre (RDC) channel. The immediate management priority is to investigate RDC delivery delays and weak destination-country performance, alongside continued product-specific price monitoring. | I10: The historical ARV distribution records show that 86.92% of evaluated deliveries arrived on or before schedule, but late shipments averaged 21.49 days beyond the scheduled date. Recorded weighted pack prices declined across major ARV presentations, while distribution activity was concentrated in the Regional Distribution Centre (RDC) channel. The immediate management priority is to investigate RDC delivery delays and weak destination-country performance, alongside continued product-specific price monitoring. | J10: The historical ARV distribution records show that 86.92% of evaluated deliveries arrived on or before schedule, but late shipments averaged 21.49 days beyond the scheduled date. Recorded weighted pack prices declined across major ARV presentations, while distribution activity was concentrated in the Regional Distribution Centre (RDC) channel. The immediate management priority is to investigate RDC delivery delays and weak destination-country performance, alongside continued product-specific price monitoring. | K10: The historical ARV distribution records show that 86.92% of evaluated deliveries arrived on or before schedule, but late shipments averaged 21.49 days beyond the scheduled date. Recorded weighted pack prices declined across major ARV presentations, while distribution activity was concentrated in the Regional Distribution Centre (RDC) channel. The immediate management priority is to investigate RDC delivery delays and weak destination-country performance, alongside continued product-specific price monitoring. | L10: The historical ARV distribution records show that 86.92% of evaluated deliveries arrived on or before schedule, but late shipments averaged 21.49 days beyond the scheduled date. Recorded weighted pack prices declined across major ARV presentations, while distribution activity was concentrated in the Regional Distribution Centre (RDC) channel. The immediate management priority is to investigate RDC delivery delays and weak destination-country performance, alongside continued product-specific price monitoring.
B11: The historical ARV distribution records show that 86.92% of evaluated deliveries arrived on or before schedule, but late shipments averaged 21.49 days beyond the scheduled date. Recorded weighted pack prices declined across major ARV presentations, while distribution activity was concentrated in the Regional Distribution Centre (RDC) channel. The immediate management priority is to investigate RDC delivery delays and weak destination-country performance, alongside continued product-specific price monitoring. | C11: The historical ARV distribution records show that 86.92% of evaluated deliveries arrived on or before schedule, but late shipments averaged 21.49 days beyond the scheduled date. Recorded weighted pack prices declined across major ARV presentations, while distribution activity was concentrated in the Regional Distribution Centre (RDC) channel. The immediate management priority is to investigate RDC delivery delays and weak destination-country performance, alongside continued product-specific price monitoring. | D11: The historical ARV distribution records show that 86.92% of evaluated deliveries arrived on or before schedule, but late shipments averaged 21.49 days beyond the scheduled date. Recorded weighted pack prices declined across major ARV presentations, while distribution activity was concentrated in the Regional Distribution Centre (RDC) channel. The immediate management priority is to investigate RDC delivery delays and weak destination-country performance, alongside continued product-specific price monitoring. | E11: The historical ARV distribution records show that 86.92% of evaluated deliveries arrived on or before schedule, but late shipments averaged 21.49 days beyond the scheduled date. Recorded weighted pack prices declined across major ARV presentations, while distribution activity was concentrated in the Regional Distribution Centre (RDC) channel. The immediate management priority is to investigate RDC delivery delays and weak destination-country performance, alongside continued product-specific price monitoring. | F11: The historical ARV distribution records show that 86.92% of evaluated deliveries arrived on or before schedule, but late shipments averaged 21.49 days beyond the scheduled date. Recorded weighted pack prices declined across major ARV presentations, while distribution activity was concentrated in the Regional Distribution Centre (RDC) channel. The immediate management priority is to investigate RDC delivery delays and weak destination-country performance, alongside continued product-specific price monitoring. | G11: The historical ARV distribution records show that 86.92% of evaluated deliveries arrived on or before schedule, but late shipments averaged 21.49 days beyond the scheduled date. Recorded weighted pack prices declined across major ARV presentations, while distribution activity was concentrated in the Regional Distribution Centre (RDC) channel. The immediate management priority is to investigate RDC delivery delays and weak destination-country performance, alongside continued product-specific price monitoring. | H11: The historical ARV distribution records show that 86.92% of evaluated deliveries arrived on or before schedule, but late shipments averaged 21.49 days beyond the scheduled date. Recorded weighted pack prices declined across major ARV presentations, while distribution activity was concentrated in the Regional Distribution Centre (RDC) channel. The immediate management priority is to investigate RDC delivery delays and weak destination-country performance, alongside continued product-specific price monitoring. | I11: The historical ARV distribution records show that 86.92% of evaluated deliveries arrived on or before schedule, but late shipments averaged 21.49 days beyond the scheduled date. Recorded weighted pack prices declined across major ARV presentations, while distribution activity was concentrated in the Regional Distribution Centre (RDC) channel. The immediate management priority is to investigate RDC delivery delays and weak destination-country performance, alongside continued product-specific price monitoring. | J11: The historical ARV distribution records show that 86.92% of evaluated deliveries arrived on or before schedule, but late shipments averaged 21.49 days beyond the scheduled date. Recorded weighted pack prices declined across major ARV presentations, while distribution activity was concentrated in the Regional Distribution Centre (RDC) channel. The immediate management priority is to investigate RDC delivery delays and weak destination-country performance, alongside continued product-specific price monitoring. | K11: The historical ARV distribution records show that 86.92% of evaluated deliveries arrived on or before schedule, but late shipments averaged 21.49 days beyond the scheduled date. Recorded weighted pack prices declined across major ARV presentations, while distribution activity was concentrated in the Regional Distribution Centre (RDC) channel. The immediate management priority is to investigate RDC delivery delays and weak destination-country performance, alongside continued product-specific price monitoring. | L11: The historical ARV distribution records show that 86.92% of evaluated deliveries arrived on or before schedule, but late shipments averaged 21.49 days beyond the scheduled date. Recorded weighted pack prices declined across major ARV presentations, while distribution activity was concentrated in the Regional Distribution Centre (RDC) channel. The immediate management priority is to investigate RDC delivery delays and weak destination-country performance, alongside continued product-specific price monitoring.
B13: 1 TIMELY DELIVERY
B14: Delivery timeliness was assessed using 1,330 unique ASN/DN references, avoiding double counting when a delivery contained multiple product lines. An on-time delivery arrived on or before its scheduled delivery date. | C14: Delivery timeliness was assessed using 1,330 unique ASN/DN references, avoiding double counting when a delivery contained multiple product lines. An on-time delivery arrived on or before its scheduled delivery date. | D14: Delivery timeliness was assessed using 1,330 unique ASN/DN references, avoiding double counting when a delivery contained multiple product lines. An on-time delivery arrived on or before its scheduled delivery date. | E14: Delivery timeliness was assessed using 1,330 unique ASN/DN references, avoiding double counting when a delivery contained multiple product lines. An on-time delivery arrived on or before its scheduled delivery date. | F14: Delivery timeliness was assessed using 1,330 unique ASN/DN references, avoiding double counting when a delivery contained multiple product lines. An on-time delivery arrived on or before its scheduled delivery date. | G14: Delivery timeliness was assessed using 1,330 unique ASN/DN references, avoiding double counting when a delivery contained multiple product lines. An on-time delivery arrived on or before its scheduled delivery date. | H14: Delivery timeliness was assessed using 1,330 unique ASN/DN references, avoiding double counting when a delivery contained multiple product lines. An on-time delivery arrived on or before its scheduled delivery date. | I14: Delivery timeliness was assessed using 1,330 unique ASN/DN references, avoiding double counting when a delivery contained multiple product lines. An on-time delivery arrived on or before its scheduled delivery date. | J14: Delivery timeliness was assessed using 1,330 unique ASN/DN references, avoiding double counting when a delivery contained multiple product lines. An on-time delivery arrived on or before its scheduled delivery date. | K14: Delivery timeliness was assessed using 1,330 unique ASN/DN references, avoiding double counting when a delivery contained multiple product lines. An on-time delivery arrived on or before its scheduled delivery date. | L14: Delivery timeliness was assessed using 1,330 unique ASN/DN references, avoiding double counting when a delivery contained multiple product lines. An on-time delivery arrived on or before its scheduled delivery date.
B15: Delivery timeliness was assessed using 1,330 unique ASN/DN references, avoiding double counting when a delivery contained multiple product lines. An on-time delivery arrived on or before its scheduled delivery date. | C15: Delivery timeliness was assessed using 1,330 unique ASN/DN references, avoiding double counting when a delivery contained multiple product lines. An on-time delivery arrived on or before its scheduled delivery date. | D15: Delivery timeliness was assessed using 1,330 unique ASN/DN references, avoiding double counting when a delivery contained multiple product lines. An on-time delivery arrived on or before its scheduled delivery date. | E15: Delivery timeliness was assessed using 1,330 unique ASN/DN references, avoiding double counting when a delivery contained multiple product lines. An on-time delivery arrived on or before its scheduled delivery date. | F15: Delivery timeliness was assessed using 1,330 unique ASN/DN references, avoiding double counting when a delivery contained multiple product lines. An on-time delivery arrived on or before its scheduled delivery date. | G15: Delivery timeliness was assessed using 1,330 unique ASN/DN references, avoiding double counting when a delivery contained multiple product lines. An on-time delivery arrived on or before its scheduled delivery date. | H15: Delivery timeliness was assessed using 1,330 unique ASN/DN references, avoiding double counting when a delivery contained multiple product lines. An on-time delivery arrived on or before its scheduled delivery date. | I15: Delivery timeliness was assessed using 1,330 unique ASN/DN references, avoiding double counting when a delivery contained multiple product lines. An on-time delivery arrived on or before its scheduled delivery date. | J15: Delivery timeliness was assessed using 1,330 unique ASN/DN references, avoiding double counting when a delivery contained multiple product lines. An on-time delivery arrived on or before its scheduled delivery date. | K15: Delivery timeliness was assessed using 1,330 unique ASN/DN references, avoiding double counting when a delivery contained multiple product lines. An on-time delivery arrived on or before its scheduled delivery date. | L15: Delivery timeliness was assessed using 1,330 unique ASN/DN references, avoiding double counting when a delivery contained multiple product lines. An on-time delivery arrived on or before its scheduled delivery date.
B17: MEASURE | E17: EVIDENCE | H17: MANAGEMENT RELEVANCE
B18: Overall delivery performance | E18: 1,156 on time / 174 late; OTD 86.92% | H18: Most evaluated deliveries met schedule, but 13.08% arrived late.
B19: Severity of late delivery | E19: Average 21.49 days; median 12 days; maximum 280 days | H19: The difference between average and median suggests that some lengthy delays increase the mean. The 280-day case merits validation.
B20: Destination-country performance | E20: Burundi: 48.57% OTD (17/35); Rwanda: 91.09% (276/303) | H20: Burundi is the clearest proportional concern; Kenya’s 100% OTD is based on just 3 deliveries.
B21: Fulfillment-channel performance | E21: Direct Drop: 97.03% (425/438); RDC: 81.95% (731/892) | H21: RDC accounts for 161 of the 174 late deliveries, indicating a priority for operational review.
B22: Direct Drop vendor observation | E22: Aurobindo: 87.62% OTD (92/105); 13 late deliveries | H22: All recorded Direct Drop delays were associated with this vendor; investigate events without assuming causation.
B24: 2 REASONABLE PROCUREMENT COST
B25: Recorded commodity value totaled $282.65 million across 35.12 million packs. A quantity-weighted pack price (sum of line-item value ÷ sum of pack quantity) was used to assess historical price movement for identical ARV presentations, rather than combining unlike medicines into one price comparison. | C25: Recorded commodity value totaled $282.65 million across 35.12 million packs. A quantity-weighted pack price (sum of line-item value ÷ sum of pack quantity) was used to assess historical price movement for identical ARV presentations, rather than combining unlike medicines into one price comparison. | D25: Recorded commodity value totaled $282.65 million across 35.12 million packs. A quantity-weighted pack price (sum of line-item value ÷ sum of pack quantity) was used to assess historical price movement for identical ARV presentations, rather than combining unlike medicines into one price comparison. | E25: Recorded commodity value totaled $282.65 million across 35.12 million packs. A quantity-weighted pack price (sum of line-item value ÷ sum of pack quantity) was used to assess historical price movement for identical ARV presentations, rather than combining unlike medicines into one price comparison. | F25: Recorded commodity value totaled $282.65 million across 35.12 million packs. A quantity-weighted pack price (sum of line-item value ÷ sum of pack quantity) was used to assess historical price movement for identical ARV presentations, rather than combining unlike medicines into one price comparison. | G25: Recorded commodity value totaled $282.65 million across 35.12 million packs. A quantity-weighted pack price (sum of line-item value ÷ sum of pack quantity) was used to assess historical price movement for identical ARV presentations, rather than combining unlike medicines into one price comparison. | H25: Recorded commodity value totaled $282.65 million across 35.12 million packs. A quantity-weighted pack price (sum of line-item value ÷ sum of pack quantity) was used to assess historical price movement for identical ARV presentations, rather than combining unlike medicines into one price comparison. | I25: Recorded commodity value totaled $282.65 million across 35.12 million packs. A quantity-weighted pack price (sum of line-item value ÷ sum of pack quantity) was used to assess historical price movement for identical ARV presentations, rather than combining unlike medicines into one price comparison. | J25: Recorded commodity value totaled $282.65 million across 35.12 million packs. A quantity-weighted pack price (sum of line-item value ÷ sum of pack quantity) was used to assess historical price movement for identical ARV presentations, rather than combining unlike medicines into one price comparison. | K25: Recorded commodity value totaled $282.65 million across 35.12 million packs. A quantity-weighted pack price (sum of line-item value ÷ sum of pack quantity) was used to assess historical price movement for identical ARV presentations, rather than combining unlike medicines into one price comparison. | L25: Recorded commodity value totaled $282.65 million across 35.12 million packs. A quantity-weighted pack price (sum of line-item value ÷ sum of pack quantity) was used to assess historical price movement for identical ARV presentations, rather than combining unlike medicines into one price comparison.
